<sdf version='1.10'>
  <world name='empty'>
    <physics name='1ms' type='ignored'>
      <max_step_size>0.001</max_step_size>
      <real_time_factor>1</real_time_factor>
      <real_time_update_rate>1000</real_time_update_rate>
    </physics>
    <plugin name='gz::sim::systems::Physics' filename='gz-sim-physics-system'/>
    <plugin name='gz::sim::systems::UserCommands' filename='gz-sim-user-commands-system'/>
    <plugin name='gz::sim::systems::SceneBroadcaster' filename='gz-sim-scene-broadcaster-system'/>
    <plugin name='gz::sim::systems::Contact' filename='gz-sim-contact-system'/>
    <gravity>0 0 -9.8000000000000007</gravity>
    <magnetic_field>5.5644999999999998e-06 2.2875799999999999e-05 -4.2388400000000002e-05</magnetic_field>
    <atmosphere type='adiabatic'/>
    <scene>
      <ambient>0.400000006 0.400000006 0.400000006 1</ambient>
      <background>0.699999988 0.699999988 0.699999988 1</background>
      <shadows>true</shadows>
    </scene>
    <model name='ground_plane'>
      <static>true</static>
      <link name='link'>
        <collision name='collision'>
          <geometry>
            <plane>
              <normal>0 0 1</normal>
              <size>100 100</size>
            </plane>
          </geometry>
          <surface>
            <friction>
              <ode/>
            </friction>
            <bounce/>
            <contact/>
          </surface>
        </collision>
        <visual name='visual'>
          <geometry>
            <plane>
              <normal>0 0 1</normal>
              <size>100 100</size>
            </plane>
          </geometry>
          <material>
            <ambient>0.800000012 0.800000012 0.800000012 1</ambient>
            <diffuse>0.800000012 0.800000012 0.800000012 1</diffuse>
            <specular>0.800000012 0.800000012 0.800000012 1</specular>
          </material>
        </visual>
        <pose>0 0 0 0 0 0</pose>
        <inertial>
          <pose>0 0 0 0 0 0</pose>
          <mass>1</mass>
          <inertia>
            <ixx>1</ixx>
            <ixy>0</ixy>
            <ixz>0</ixz>
            <iyy>1</iyy>
            <iyz>0</iyz>
            <izz>1</izz>
          </inertia>
        </inertial>
        <enable_wind>false</enable_wind>
      </link>
      <pose>0 0 0 0 0 0</pose>
      <self_collide>false</self_collide>
    </model>
    <model name='agribot'>
      <link name='base_footprint'>
        <inertial>
          <pose>0.026888595576601719 -0.00022857048424687739 0.23289435111511281 0 0 0</pose>
          <mass>4.3181279999999997</mass>
          <inertia>
            <ixx>0.1082633282381921</ixx>
            <ixy>-3.3557788600149663e-05</ixy>
            <ixz>-0.003562017763863726</ixz>
            <iyy>0.1194583984893426</iyy>
            <iyz>0.00012697845779233459</iyz>
            <izz>0.14874671999492889</izz>
          </inertia>
        </inertial>
        <collision name='base_footprint_fixed_joint_lump__base_link_collision'>
          <pose>0 0 0.27431 0 0 0</pose>
          <geometry>
            <box>
              <size>0.19986000000000001 0.42380000000000001 0.0269</size>
            </box>
          </geometry>
          <surface>
            <friction>
              <ode/>
            </friction>
            <bounce/>
            <contact/>
          </surface>
        </collision>
        <collision name='base_footprint_fixed_joint_lump__base_link_collision_1'>
          <pose>0.21986 0.20380000000000001 0.15372 3.1415926535897931 0.88659265358979344 3.1415926535897931</pose>
          <geometry>
            <cylinder>
              <length>0.35680000000000001</length>
              <radius>0.011900000000000001</radius>
            </cylinder>
          </geometry>
          <surface>
            <friction>
              <ode/>
            </friction>
            <bounce/>
            <contact/>
          </surface>
        </collision>
        <collision name='base_footprint_fixed_joint_lump__base_link_collision_2'>
          <pose>0.21986 -0.20380000000000001 0.15372 3.1415926535897931 0.88659265358979344 3.1415926535897931</pose>
          <geometry>
            <cylinder>
              <length>0.35680000000000001</length>
              <radius>0.011900000000000001</radius>
            </cylinder>
          </geometry>
          <surface>
            <friction>
              <ode/>
            </friction>
            <bounce/>
            <contact/>
          </surface>
        </collision>
        <collision name='base_footprint_fixed_joint_lump__base_link_collision_3'>
          <pose>-0.12493 0.20380000000000001 0.231845 0 0.78500000000000036 0</pose>
          <geometry>
            <cylinder>
              <length>0.10493</length>
              <radius>0.011900000000000001</radius>
            </cylinder>
          </geometry>
          <surface>
            <friction>
              <ode/>
            </friction>
            <bounce/>
            <contact/>
          </surface>
        </collision>
        <collision name='base_footprint_fixed_joint_lump__base_link_collision_4'>
          <pose>-0.246395 0.20380000000000001 0.11038000000000001 0 0.78500000000000036 0</pose>
          <geometry>
            <cylinder>
              <length>0.24293000000000001</length>
              <radius>0.011900000000000001</radius>
            </cylinder>
          </geometry>
          <surface>
            <friction>
              <ode/>
            </friction>
            <bounce/>
            <contact/>
          </surface>
        </collision>
        <collision name='base_footprint_fixed_joint_lump__base_link_collision_5'>
          <pose>-0.086395 0.20380000000000001 0.11038000000000001 3.1415926535897931 0.88659265358979344 3.1415926535897931</pose>
          <geometry>
            <cylinder>
              <length>0.24293000000000001</length>
              <radius>0.011900000000000001</radius>
            </cylinder>
          </geometry>
          <surface>
            <friction>
              <ode/>
            </friction>
            <bounce/>
            <contact/>
          </surface>
        </collision>
        <collision name='base_footprint_fixed_joint_lump__base_link_collision_6'>
          <pose>-0.12493 -0.20380000000000001 0.231845 0 0.78500000000000036 0</pose>
          <geometry>
            <cylinder>
              <length>0.10493</length>
              <radius>0.011900000000000001</radius>
            </cylinder>
          </geometry>
          <surface>
            <friction>
              <ode/>
            </friction>
            <bounce/>
            <contact/>
          </surface>
        </collision>
        <collision name='base_footprint_fixed_joint_lump__base_link_collision_7'>
          <pose>-0.246395 -0.20380000000000001 0.11038000000000001 0 0.78500000000000036 0</pose>
          <geometry>
            <cylinder>
              <length>0.24293000000000001</length>
              <radius>0.011900000000000001</radius>
            </cylinder>
          </geometry>
          <surface>
            <friction>
              <ode/>
            </friction>
            <bounce/>
            <contact/>
          </surface>
        </collision>
        <collision name='base_footprint_fixed_joint_lump__base_link_collision_8'>
          <pose>-0.086395 -0.20380000000000001 0.11038000000000001 3.1415926535897931 0.88659265358979344 3.1415926535897931</pose>
          <geometry>
            <cylinder>
              <length>0.24293000000000001</length>
              <radius>0.011900000000000001</radius>
            </cylinder>
          </geometry>
          <surface>
            <friction>
              <ode/>
            </friction>
            <bounce/>
            <contact/>
          </surface>
        </collision>
        <collision name='base_footprint_fixed_joint_lump__lidar_visual_collision_9'>
          <pose>0.070000000000000007 -0.014999999999999999 0.31430999999999998 0 0 0</pose>
          <geometry>
            <cylinder>
              <length>0.050000000000000003</length>
              <radius>0.040000000000000001</radius>
            </cylinder>
          </geometry>
          <surface>
            <friction>
              <ode/>
            </friction>
            <bounce/>
            <contact/>
          </surface>
        </collision>
        <collision name='base_footprint_fixed_joint_lump__imu_link_visual_collision_10'>
          <pose>0.058999999999999997 0.10199999999999999 0.30131000000000002 0 0 0</pose>
          <geometry>
            <box>
              <size>0.029999999999999999 0.02 0.01</size>
            </box>
          </geometry>
          <surface>
            <friction>
              <ode/>
            </friction>
            <bounce/>
            <contact/>
          </surface>
        </collision>
        <visual name='base_footprint_fixed_joint_lump__base_link_visual'>
          <pose>0 0 0.27431 0 0 0</pose>
          <geometry>
            <mesh>
              <scale>0.001 0.001 0.001</scale>
              <uri>file:///home/sushant/project_ws/install/agribot_description/share/agribot_description/meshes/agribot_baselink.stl</uri>
            </mesh>
          </geometry>
        </visual>
        <visual name='base_footprint_fixed_joint_lump__lidar_visual_visual_1'>
          <pose>0.070000000000000007 -0.014999999999999999 0.31430999999999998 0 0 0</pose>
          <geometry>
            <cylinder>
              <length>0.050000000000000003</length>
              <radius>0.040000000000000001</radius>
            </cylinder>
          </geometry>
        </visual>
        <visual name='base_footprint_fixed_joint_lump__imu_link_visual_visual_2'>
          <pose>0.058999999999999997 0.10199999999999999 0.30131000000000002 0 0 0</pose>
          <geometry>
            <box>
              <size>0.029999999999999999 0.02 0.01</size>
            </box>
          </geometry>
        </visual>
        <sensor name='gpu_lidar' type='gpu_lidar'>
          <pose>0.070000000000000007 -0.014999999999999999 0.31430999999999998 0 0 0</pose>
          <topic>/scan</topic>
          <update_rate>20</update_rate>
          <enable_metrics>false</enable_metrics>
          <lidar>
            <scan>
              <horizontal>
                <samples>720</samples>
                <resolution>1</resolution>
                <min_angle>-3.1415899999999999</min_angle>
                <max_angle>3.1415899999999999</max_angle>
              </horizontal>
              <vertical>
                <samples>1</samples>
                <min_angle>0</min_angle>
                <max_angle>0</max_angle>
                <resolution>1</resolution>
              </vertical>
            </scan>
            <range>
              <min>0.050000000000000003</min>
              <max>12</max>
              <resolution>0.01</resolution>
            </range>
            <noise>
              <type>gaussian</type>
              <mean>0</mean>
              <stddev>0.01</stddev>
            </noise>
            <visibility_mask>4294967295</visibility_mask>
          </lidar>
        </sensor>
        <sensor name='imu_sensor' type='imu'>
          <pose>0.058999999999999997 0.10199999999999999 0.30131000000000002 0 0 0</pose>
          <topic>/imu</topic>
          <update_rate>100</update_rate>
          <enable_metrics>false</enable_metrics>
          <imu>
            <orientation_reference_frame>
              <localization>CUSTOM</localization>
              <custom_rpy>0 0 0</custom_rpy>
              <grav_dir_x>1 0 0</grav_dir_x>
            </orientation_reference_frame>
            <angular_velocity>
              <x>
                <noise type='gaussian'>
                  <mean>0</mean>
                  <stddev>0.001</stddev>
                  <bias_mean>0</bias_mean>
                  <bias_stddev>0</bias_stddev>
                  <dynamic_bias_stddev>0</dynamic_bias_stddev>
                  <dynamic_bias_correlation_time>0</dynamic_bias_correlation_time>
                  <precision>0</precision>
                </noise>
              </x>
              <y>
                <noise type='gaussian'>
                  <mean>0</mean>
                  <stddev>0.001</stddev>
                  <bias_mean>0</bias_mean>
                  <bias_stddev>0</bias_stddev>
                  <dynamic_bias_stddev>0</dynamic_bias_stddev>
                  <dynamic_bias_correlation_time>0</dynamic_bias_correlation_time>
                  <precision>0</precision>
                </noise>
              </y>
              <z>
                <noise type='gaussian'>
                  <mean>0</mean>
                  <stddev>0.001</stddev>
                  <bias_mean>0</bias_mean>
                  <bias_stddev>0</bias_stddev>
                  <dynamic_bias_stddev>0</dynamic_bias_stddev>
                  <dynamic_bias_correlation_time>0</dynamic_bias_correlation_time>
                  <precision>0</precision>
                </noise>
              </z>
            </angular_velocity>
            <linear_acceleration>
              <x>
                <noise type='gaussian'>
                  <mean>0</mean>
                  <stddev>0.01</stddev>
                  <bias_mean>0</bias_mean>
                  <bias_stddev>0</bias_stddev>
                  <dynamic_bias_stddev>0</dynamic_bias_stddev>
                  <dynamic_bias_correlation_time>0</dynamic_bias_correlation_time>
                  <precision>0</precision>
                </noise>
              </x>
              <y>
                <noise type='gaussian'>
                  <mean>0</mean>
                  <stddev>0.01</stddev>
                  <bias_mean>0</bias_mean>
                  <bias_stddev>0</bias_stddev>
                  <dynamic_bias_stddev>0</dynamic_bias_stddev>
                  <dynamic_bias_correlation_time>0</dynamic_bias_correlation_time>
                  <precision>0</precision>
                </noise>
              </y>
              <z>
                <noise type='gaussian'>
                  <mean>0</mean>
                  <stddev>0.01</stddev>
                  <bias_mean>0</bias_mean>
                  <bias_stddev>0</bias_stddev>
                  <dynamic_bias_stddev>0</dynamic_bias_stddev>
                  <dynamic_bias_correlation_time>0</dynamic_bias_correlation_time>
                  <precision>0</precision>
                </noise>
              </z>
            </linear_acceleration>
            <enable_orientation>true</enable_orientation>
          </imu>
        </sensor>
        <pose>0 0 0 0 0 0</pose>
        <enable_wind>false</enable_wind>
      </link>
      <joint name='left_wheel_front_joint' type='revolute'>
        <pose>0 0 0 0 0 0</pose>
        <parent>base_footprint</parent>
        <child>left_wheel_link_front</child>
        <axis>
          <xyz>0 1 0</xyz>
          <limit>
            <lower>-inf</lower>
            <upper>inf</upper>
            <effort>inf</effort>
            <velocity>inf</velocity>
            <stiffness>100000000</stiffness>
            <dissipation>1</dissipation>
          </limit>
          <dynamics>
            <spring_reference>0</spring_reference>
            <spring_stiffness>0</spring_stiffness>
            <damping>0</damping>
            <friction>0</friction>
          </dynamics>
        </axis>
      </joint>
      <link name='left_wheel_link_front'>
        <pose>0.35606000000000004 0.22972999999999996 0.048990000000000027 1.1823318708532346e-33 -2.0685613861653744e-18 -1.2228630268398336e-51</pose>
        <inertial>
          <pose>0 0.0015120000000000001 0 0 0 0</pose>
          <mass>0.22366900000000001</mass>
          <inertia>
            <ixx>0.000183</ixx>
            <ixy>0</ixy>
            <ixz>0</ixz>
            <iyy>0.00032860000000000002</iyy>
            <iyz>0</iyz>
            <izz>0.000183</izz>
          </inertia>
        </inertial>
        <collision name='left_wheel_link_front_collision'>
          <pose>0 0 0 1.5700000000000001 0 0</pose>
          <geometry>
            <cylinder>
              <length>0.044999999999999998</length>
              <radius>0.051999999999999998</radius>
            </cylinder>
          </geometry>
          <surface>
            <friction>
              <ode/>
            </friction>
            <bounce/>
            <contact/>
          </surface>
        </collision>
        <visual name='left_wheel_link_front_visual'>
          <pose>0 0 0 0 0 0</pose>
          <geometry>
            <mesh>
              <scale>0.001 0.001 0.001</scale>
              <uri>file:///home/sushant/project_ws/install/agribot_description/share/agribot_description/meshes/agribot_left_wheel.stl</uri>
            </mesh>
          </geometry>
        </visual>
        <enable_wind>false</enable_wind>
      </link>
      <joint name='left_wheel_mid_joint' type='revolute'>
        <pose>0 0 0 0 0 0</pose>
        <parent>base_footprint</parent>
        <child>left_wheel_link_mid</child>
        <axis>
          <xyz>0 1 0</xyz>
          <limit>
            <lower>-inf</lower>
            <upper>inf</upper>
            <effort>inf</effort>
            <velocity>inf</velocity>
            <stiffness>100000000</stiffness>
            <dissipation>1</dissipation>
          </limit>
          <dynamics>
            <spring_reference>0</spring_reference>
            <spring_stiffness>0</spring_stiffness>
            <damping>0</damping>
            <friction>0</friction>
          </dynamics>
        </axis>
      </joint>
      <link name='left_wheel_link_mid'>
        <pose>0.0063499999999999997 0.22972999999999999 0.048990000000000034 1.932339878348071e-33 -3.380746115999069e-18 1.9721522630525295e-31</pose>
        <inertial>
          <pose>0 0.0015120000000000001 0 0 0 0</pose>
          <mass>0.22366900000000001</mass>
          <inertia>
            <ixx>0.000183</ixx>
            <ixy>0</ixy>
            <ixz>0</ixz>
            <iyy>0.00032860000000000002</iyy>
            <iyz>0</iyz>
            <izz>0.000183</izz>
          </inertia>
        </inertial>
        <collision name='left_wheel_link_mid_collision'>
          <pose>0 0 0 1.5700000000000001 0 0</pose>
          <geometry>
            <cylinder>
              <length>0.044999999999999998</length>
              <radius>0.051999999999999998</radius>
            </cylinder>
          </geometry>
          <surface>
            <friction>
              <ode/>
            </friction>
            <bounce/>
            <contact/>
          </surface>
        </collision>
        <visual name='left_wheel_link_mid_visual'>
          <pose>0 0 0 0 0 0</pose>
          <geometry>
            <mesh>
              <scale>0.001 0.001 0.001</scale>
              <uri>file:///home/sushant/project_ws/install/agribot_description/share/agribot_description/meshes/agribot_left_wheel.stl</uri>
            </mesh>
          </geometry>
        </visual>
        <enable_wind>false</enable_wind>
      </link>
      <joint name='left_wheel_rear_joint' type='revolute'>
        <pose>0 0 0 0 0 0</pose>
        <parent>base_footprint</parent>
        <child>left_wheel_link_rear</child>
        <axis>
          <xyz>0 1 0</xyz>
          <limit>
            <lower>-inf</lower>
            <upper>inf</upper>
            <effort>inf</effort>
            <velocity>inf</velocity>
            <stiffness>100000000</stiffness>
            <dissipation>1</dissipation>
          </limit>
          <dynamics>
            <spring_reference>0</spring_reference>
            <spring_stiffness>0</spring_stiffness>
            <damping>0</damping>
            <friction>0</friction>
          </dynamics>
        </axis>
      </joint>
      <link name='left_wheel_link_rear'>
        <pose>-0.29605999999999993 0.22972999999999999 0.048990000000000034 1.0439603900561122e-33 -1.8264720906507049e-18 -9.5338225809115629e-52</pose>
        <inertial>
          <pose>0 0.0015120000000000001 0 0 0 0</pose>
          <mass>0.22366900000000001</mass>
          <inertia>
            <ixx>0.000183</ixx>
            <ixy>0</ixy>
            <ixz>0</ixz>
            <iyy>0.00032860000000000002</iyy>
            <iyz>0</iyz>
            <izz>0.000183</izz>
          </inertia>
        </inertial>
        <collision name='left_wheel_link_rear_collision'>
          <pose>0 0 0 1.5700000000000001 0 0</pose>
          <geometry>
            <cylinder>
              <length>0.044999999999999998</length>
              <radius>0.051999999999999998</radius>
            </cylinder>
          </geometry>
          <surface>
            <friction>
              <ode/>
            </friction>
            <bounce/>
            <contact/>
          </surface>
        </collision>
        <visual name='left_wheel_link_rear_visual'>
          <pose>0 0 0 0 0 0</pose>
          <geometry>
            <mesh>
              <scale>0.001 0.001 0.001</scale>
              <uri>file:///home/sushant/project_ws/install/agribot_description/share/agribot_description/meshes/agribot_left_wheel.stl</uri>
            </mesh>
          </geometry>
        </visual>
        <enable_wind>false</enable_wind>
      </link>
      <joint name='right_wheel_front_joint' type='revolute'>
        <pose>0 0 0 0 0 0</pose>
        <parent>base_footprint</parent>
        <child>right_wheel_link_front</child>
        <axis>
          <xyz>0 1 0</xyz>
          <limit>
            <lower>-inf</lower>
            <upper>inf</upper>
            <effort>inf</effort>
            <velocity>inf</velocity>
            <stiffness>100000000</stiffness>
            <dissipation>1</dissipation>
          </limit>
          <dynamics>
            <spring_reference>0</spring_reference>
            <spring_stiffness>0</spring_stiffness>
            <damping>0</damping>
            <friction>0</friction>
          </dynamics>
        </axis>
      </joint>
      <link name='right_wheel_link_front'>
        <pose>0.35605999999999993 -0.22973000000000002 0.04899000000000004 2.620073501214205e-33 -4.5839777174745763e-18 -6.0051792738557564e-51</pose>
        <inertial>
          <pose>0 0.0015120000000000001 0 0 0 0</pose>
          <mass>0.22366900000000001</mass>
          <inertia>
            <ixx>0.000183</ixx>
            <ixy>0</ixy>
            <ixz>0</ixz>
            <iyy>0.00032860000000000002</iyy>
            <iyz>0</iyz>
            <izz>0.000183</izz>
          </inertia>
        </inertial>
        <collision name='right_wheel_link_front_collision'>
          <pose>0 0 0 1.5700000000000001 0 0</pose>
          <geometry>
            <cylinder>
              <length>0.044999999999999998</length>
              <radius>0.051999999999999998</radius>
            </cylinder>
          </geometry>
          <surface>
            <friction>
              <ode/>
            </friction>
            <bounce/>
            <contact/>
          </surface>
        </collision>
        <visual name='right_wheel_link_front_visual'>
          <pose>0 0 0 0 0 0</pose>
          <geometry>
            <mesh>
              <scale>0.001 0.001 0.001</scale>
              <uri>file:///home/sushant/project_ws/install/agribot_description/share/agribot_description/meshes/agribot_right_wheel.stl</uri>
            </mesh>
          </geometry>
        </visual>
        <enable_wind>false</enable_wind>
      </link>
      <joint name='right_wheel_mid_joint' type='revolute'>
        <pose>0 0 0 0 0 0</pose>
        <parent>base_footprint</parent>
        <child>right_wheel_link_mid</child>
        <axis>
          <xyz>0 1 0</xyz>
          <limit>
            <lower>-inf</lower>
            <upper>inf</upper>
            <effort>inf</effort>
            <velocity>inf</velocity>
            <stiffness>100000000</stiffness>
            <dissipation>1</dissipation>
          </limit>
          <dynamics>
            <spring_reference>0</spring_reference>
            <spring_stiffness>0</spring_stiffness>
            <damping>0</damping>
            <friction>0</friction>
          </dynamics>
        </axis>
      </joint>
      <link name='right_wheel_link_mid'>
        <pose>0.006349999999999998 -0.22972999999999999 0.04899000000000004 2.2480276106335313e-33 -3.9330608148553201e-18 1.9721522630525295e-31</pose>
        <inertial>
          <pose>0 0.0015120000000000001 0 0 0 0</pose>
          <mass>0.22366900000000001</mass>
          <inertia>
            <ixx>0.000183</ixx>
            <ixy>0</ixy>
            <ixz>0</ixz>
            <iyy>0.00032860000000000002</iyy>
            <iyz>0</iyz>
            <izz>0.000183</izz>
          </inertia>
        </inertial>
        <collision name='right_wheel_link_mid_collision'>
          <pose>0 0 0 1.5700000000000001 0 0</pose>
          <geometry>
            <cylinder>
              <length>0.044999999999999998</length>
              <radius>0.051999999999999998</radius>
            </cylinder>
          </geometry>
          <surface>
            <friction>
              <ode/>
            </friction>
            <bounce/>
            <contact/>
          </surface>
        </collision>
        <visual name='right_wheel_link_mid_visual'>
          <pose>0 0 0 0 0 0</pose>
          <geometry>
            <mesh>
              <scale>0.001 0.001 0.001</scale>
              <uri>file:///home/sushant/project_ws/install/agribot_description/share/agribot_description/meshes/agribot_right_wheel.stl</uri>
            </mesh>
          </geometry>
        </visual>
        <enable_wind>false</enable_wind>
      </link>
      <joint name='right_wheel_rear_joint' type='revolute'>
        <pose>0 0 0 0 0 0</pose>
        <parent>base_footprint</parent>
        <child>right_wheel_link_rear</child>
        <axis>
          <xyz>0 1 0</xyz>
          <limit>
            <lower>-inf</lower>
            <upper>inf</upper>
            <effort>inf</effort>
            <velocity>inf</velocity>
            <stiffness>100000000</stiffness>
            <dissipation>1</dissipation>
          </limit>
          <dynamics>
            <spring_reference>0</spring_reference>
            <spring_stiffness>0</spring_stiffness>
            <damping>0</damping>
            <friction>0</friction>
          </dynamics>
        </axis>
      </joint>
      <link name='right_wheel_link_rear'>
        <pose>-0.29606000000000005 -0.22972999999999999 0.04899000000000004 2.4539789963433966e-33 -4.293385239176788e-18 -5.267938600075304e-51</pose>
        <inertial>
          <pose>0 0.0015120000000000001 0 0 0 0</pose>
          <mass>0.22366900000000001</mass>
          <inertia>
            <ixx>0.000183</ixx>
            <ixy>0</ixy>
            <ixz>0</ixz>
            <iyy>0.00032860000000000002</iyy>
            <iyz>0</iyz>
            <izz>0.000183</izz>
          </inertia>
        </inertial>
        <collision name='right_wheel_link_rear_collision'>
          <pose>0 0 0 1.5700000000000001 0 0</pose>
          <geometry>
            <cylinder>
              <length>0.044999999999999998</length>
              <radius>0.051999999999999998</radius>
            </cylinder>
          </geometry>
          <surface>
            <friction>
              <ode/>
            </friction>
            <bounce/>
            <contact/>
          </surface>
        </collision>
        <visual name='right_wheel_link_rear_visual'>
          <pose>0 0 0 0 0 0</pose>
          <geometry>
            <mesh>
              <scale>0.001 0.001 0.001</scale>
              <uri>file:///home/sushant/project_ws/install/agribot_description/share/agribot_description/meshes/agribot_right_wheel.stl</uri>
            </mesh>
          </geometry>
        </visual>
        <enable_wind>false</enable_wind>
      </link>
      <plugin name='gz_ros2_control::GazeboSimROS2ControlPlugin' filename='gz_ros2_control-system'>
        <parameters>/home/sushant/project_ws/install/agribot_controller/share/agribot_controller/config/agribot_controller.yaml</parameters>
      </plugin>
      <plugin name='gz::sim::systems::Sensors' filename='gz-sim-sensors-system'/>
      <plugin name='gz::sim::systems::Imu' filename='gz-sim-imu-system'/>
      <frame name='lidar_visual_joint' attached_to='base_laser'>
        <pose>0 0 0 0 0 0</pose>
      </frame>
      <frame name='lidar_visual' attached_to='lidar_visual_joint'>
        <pose>0 0 0 0 0 0</pose>
      </frame>
      <frame name='base_laser_joint' attached_to='base_link'>
        <pose>0.070000000000000007 -0.014999999999999999 0.040000000000000001 0 0 0</pose>
      </frame>
      <frame name='base_laser' attached_to='base_laser_joint'>
        <pose>0 0 0 0 0 0</pose>
      </frame>
      <frame name='camera_optical_joint' attached_to='camera_link'>
        <pose>0 0 0 -1.57079632679 -5.5511151231257827e-17 -1.57079632679</pose>
      </frame>
      <frame name='camera_optical_frame' attached_to='camera_optical_joint'>
        <pose>0 0 0 0 0 0</pose>
      </frame>
      <frame name='camera_joint' attached_to='base_link'>
        <pose>0.13 0 0 0 0 0</pose>
      </frame>
      <frame name='camera_link' attached_to='camera_joint'>
        <pose>0 0 0 0 0 0</pose>
      </frame>
      <frame name='imu_visual_joint' attached_to='imu_link'>
        <pose>0 0 0 0 0 0</pose>
      </frame>
      <frame name='imu_link_visual' attached_to='imu_visual_joint'>
        <pose>0 0 0 0 0 0</pose>
      </frame>
      <frame name='imu_joint' attached_to='base_link'>
        <pose>0.058999999999999997 0.10199999999999999 0.027 0 0 0</pose>
      </frame>
      <frame name='imu_link' attached_to='imu_joint'>
        <pose>0 0 0 0 0 0</pose>
      </frame>
      <frame name='base_joint' attached_to='base_footprint'>
        <pose>0 0 0.27431 0 0 0</pose>
      </frame>
      <frame name='base_link' attached_to='base_joint'>
        <pose>0 0 0 0 0 0</pose>
      </frame>
      <pose>3.2215516351141832e-12 -1.0117004422150122e-12 0.003027799702723545 3.3407705086242868e-10 1.0805456611593179e-09 -1.1427830962145368e-15</pose>
      <static>false</static>
      <self_collide>false</self_collide>
    </model>
    <model name='cylinder'>
      <pose>0.99132217676560463 -1.1185287705874418 0.49999942638036005 8.4333747234676224e-20 1.7102448131684883e-19 1.3625309784207717e-20</pose>
      <link name='cylinder_link'>
        <inertial>
          <inertia>
            <ixx>0.14580000000000001</ixx>
            <ixy>0</ixy>
            <ixz>0</ixz>
            <iyy>0.14580000000000001</iyy>
            <iyz>0</iyz>
            <izz>0.125</izz>
          </inertia>
          <mass>1</mass>
          <pose>0 0 0 0 0 0</pose>
        </inertial>
        <collision name='cylinder_collision'>
          <geometry>
            <cylinder>
              <radius>0.5</radius>
              <length>1</length>
            </cylinder>
          </geometry>
          <surface>
            <friction>
              <ode/>
            </friction>
            <bounce/>
            <contact/>
          </surface>
        </collision>
        <visual name='cylinder_visual'>
          <geometry>
            <cylinder>
              <radius>0.5</radius>
              <length>1</length>
            </cylinder>
          </geometry>
          <material>
            <ambient>0.300000012 0.300000012 0.300000012 1</ambient>
            <diffuse>0.699999988 0.699999988 0.699999988 1</diffuse>
            <specular>1 1 1 1</specular>
          </material>
        </visual>
        <pose>0 0 0 0 0 0</pose>
        <enable_wind>false</enable_wind>
      </link>
      <static>false</static>
      <self_collide>false</self_collide>
    </model>
    <model name='cylinder_0'>
      <pose>-0.43304271859991661 1.255395606499965 0.49999942638036005 2.1722424869812802e-19 5.1414305442386073e-19 7.8564475469536944e-21</pose>
      <link name='cylinder_link'>
        <inertial>
          <inertia>
            <ixx>0.14580000000000001</ixx>
            <ixy>0</ixy>
            <ixz>0</ixz>
            <iyy>0.14580000000000001</iyy>
            <iyz>0</iyz>
            <izz>0.125</izz>
          </inertia>
          <mass>1</mass>
          <pose>0 0 0 0 0 0</pose>
        </inertial>
        <collision name='cylinder_collision'>
          <geometry>
            <cylinder>
              <radius>0.5</radius>
              <length>1</length>
            </cylinder>
          </geometry>
          <surface>
            <friction>
              <ode/>
            </friction>
            <bounce/>
            <contact/>
          </surface>
        </collision>
        <visual name='cylinder_visual'>
          <geometry>
            <cylinder>
              <radius>0.5</radius>
              <length>1</length>
            </cylinder>
          </geometry>
          <material>
            <ambient>0.300000012 0.300000012 0.300000012 1</ambient>
            <diffuse>0.699999988 0.699999988 0.699999988 1</diffuse>
            <specular>1 1 1 1</specular>
          </material>
        </visual>
        <pose>0 0 0 0 0 0</pose>
        <enable_wind>false</enable_wind>
      </link>
      <static>false</static>
      <self_collide>false</self_collide>
    </model>
    <model name='cone'>
      <pose>3.5273516786793553 1.5469919925064626 0.49999999993296756 5.2548544155140844e-17 -7.7132841038066057e-10 -1.848369177196814e-23</pose>
      <link name='cone_link'>
        <inertial>
          <inertia>
            <ixx>0.074999999999999997</ixx>
            <ixy>0</ixy>
            <ixz>0</ixz>
            <iyy>0.074999999999999997</iyy>
            <iyz>0</iyz>
            <izz>0.074999999999999997</izz>
          </inertia>
          <mass>1</mass>
          <pose>0 0 0 0 0 0</pose>
        </inertial>
        <collision name='cone_collision'>
          <geometry>
            <cone>
              <radius>0.5</radius>
              <length>1</length>
            </cone>
          </geometry>
          <surface>
            <friction>
              <ode/>
            </friction>
            <bounce/>
            <contact/>
          </surface>
        </collision>
        <visual name='cone_visual'>
          <geometry>
            <cone>
              <radius>0.5</radius>
              <length>1</length>
            </cone>
          </geometry>
          <material>
            <ambient>0.300000012 0.300000012 0.300000012 1</ambient>
            <diffuse>0.699999988 0.699999988 0.699999988 1</diffuse>
            <specular>1 1 1 1</specular>
          </material>
        </visual>
        <pose>0 0 0 0 0 0</pose>
        <enable_wind>false</enable_wind>
      </link>
      <static>false</static>
      <self_collide>false</self_collide>
    </model>
    <model name='box'>
      <pose>1.1605770246655172 1.2757939043909505 0.49999999990199806 6.2287739151293738e-22 9.3279666454713669e-22 -3.6315533669320137e-22</pose>
      <link name='box_link'>
        <inertial>
          <inertia>
            <ixx>0.16666</ixx>
            <ixy>0</ixy>
            <ixz>0</ixz>
            <iyy>0.16666</iyy>
            <iyz>0</iyz>
            <izz>0.16666</izz>
          </inertia>
          <mass>1</mass>
          <pose>0 0 0 0 0 0</pose>
        </inertial>
        <collision name='box_collision'>
          <geometry>
            <box>
              <size>1 1 1</size>
            </box>
          </geometry>
          <surface>
            <friction>
              <ode/>
            </friction>
            <bounce/>
            <contact/>
          </surface>
        </collision>
        <visual name='box_visual'>
          <geometry>
            <box>
              <size>1 1 1</size>
            </box>
          </geometry>
          <material>
            <ambient>0.300000012 0.300000012 0.300000012 1</ambient>
            <diffuse>0.699999988 0.699999988 0.699999988 1</diffuse>
            <specular>1 1 1 1</specular>
          </material>
        </visual>
        <pose>0 0 0 0 0 0</pose>
        <enable_wind>false</enable_wind>
      </link>
      <static>false</static>
      <self_collide>false</self_collide>
    </model>
    <light name='sun' type='directional'>
      <pose>0 0 10 0 0 0</pose>
      <cast_shadows>true</cast_shadows>
      <intensity>1</intensity>
      <direction>-0.5 0.10000000000000001 -0.90000000000000002</direction>
      <diffuse>0.800000012 0.800000012 0.800000012 1</diffuse>
      <specular>0.200000003 0.200000003 0.200000003 1</specular>
      <attenuation>
        <range>1000</range>
        <linear>0.01</linear>
        <constant>0.90000000000000002</constant>
        <quadratic>0.001</quadratic>
      </attenuation>
      <spot>
        <inner_angle>0</inner_angle>
        <outer_angle>0</outer_angle>
        <falloff>0</falloff>
      </spot>
    </light>
  </world>
</sdf>
